<?xml version="1.0" ?><!-- =================================================================================== --><!-- |    This document was autogenerated by xacro from /home/tndrd/robokit_mv_description/urdf/robokit_mv.urdf.xacro | --><!-- |    EDITING THIS FILE BY HAND IS NOT RECOMMENDED                                 | --><!-- =================================================================================== --><!-- This URDF was automatically created by SolidWorks to URDF Exporter! Originally created by Stephen Brawner (brawner@gmail.com) 
     Commit Version: 1.5.1-0-g916b5db  Build Version: 1.5.7152.31018
     For more information, please see http://wiki.ros.org/sw_urdf_exporter --><robot name="Robokit-MV"><webots><plugin type="webots_ros2_control::Ros2Control"/><plugin type="webots_ros2_driver::Ros2IMU"><enabled>true</enabled><topicName>/imu_head</topicName><alwaysOn>true</alwaysOn><inertialUnitName>imu_head</inertialUnitName></plugin><plugin type="webots_ros2_driver::Ros2IMU"><enabled>true</enabled><topicName>/imu_body</topicName><alwaysOn>true</alwaysOn><inertialUnitName>imu_body</inertialUnitName></plugin></webots><ros2_control name="WebotsControl" type="system"><hardware><plugin>webots_ros2_control::Ros2ControlSystem</plugin></hardware><joint name="pelvis_yaw"><state_interface name="position"/><command_interface name="position"/></joint><joint name="left_hip_yaw"><state_interface name="position"/><command_interface name="position"/></joint><joint name="left_hip_roll"><state_interface name="position"/><command_interface name="position"/></joint><joint name="left_hip_pitch"><state_interface name="position"/><command_interface name="position"/></joint><joint name="left_knee"><state_interface name="position"/><command_interface name="position"/></joint><joint name="left_ankle_pitch"><state_interface name="position"/><command_interface name="position"/></joint><joint name="left_ankle_roll"><state_interface name="position"/><command_interface name="position"/></joint><joint name="right_hip_yaw"><state_interface name="position"/><command_interface name="position"/></joint><joint name="right_hip_roll"><state_interface name="position"/><command_interface name="position"/></joint><joint name="right_hip_pitch"><state_interface name="position"/><command_interface name="position"/></joint><joint name="right_knee"><state_interface name="position"/><command_interface name="position"/></joint><joint name="right_ankle_pitch"><state_interface name="position"/><command_interface name="position"/></joint><joint name="right_ankle_roll"><state_interface name="position"/><command_interface name="position"/></joint><joint name="right_shoulder_pitch"><state_interface name="position"/><command_interface name="position"/></joint><joint name="right_shoulder_roll"><state_interface name="position"/><command_interface name="position"/></joint><joint name="right_shoulder_twirl"><state_interface name="position"/><command_interface name="position"/></joint><joint name="right_elbow_pitch"><state_interface name="position"/><command_interface name="position"/></joint><joint name="left_shoulder_pitch"><state_interface name="position"/><command_interface name="position"/></joint><joint name="left_shoulder_roll"><state_interface name="position"/><command_interface name="position"/></joint><joint name="left_shoulder_twirl"><state_interface name="position"/><command_interface name="position"/></joint><joint name="left_elbow_pitch"><state_interface name="position"/><command_interface name="position"/></joint><joint name="head_yaw"><state_interface name="position"/><command_interface name="position"/></joint><joint name="head_pitch"><state_interface name="position"/><command_interface name="position"/></joint></ros2_control><link name="trunk_1"><inertial><origin rpy="0 0 0" xyz="-8.74167832816907E-07 0.023372900132223 0.0410889489067618"/><mass value="0.214867806570214"/><inertia ixx="5.81804713501468E-05" ixy="1.62345797802086E-11" ixz="5.51184024287373E-10" iyy="7.51266691454446E-05" iyz="2.13270086422374E-06" izz="8.82233769036687E-05"/></inertial><visual><origin rpy="0 0 0" xyz="0 0 0"/><geometry><mesh filename="package://robokit_mv_description/meshes/trunk_1.STL"/></geometry><material name=""><color rgba="0.792156862745098 0.819607843137255 0.933333333333333 1"/></material></visual><collision><origin rpy="0 0 0" xyz="0 0 0"/><geometry><mesh filename="package://robokit_mv_description/meshes/trunk_1.STL"/></geometry></collision></link><link name="Waist"><inertial><origin rpy="0 0 0" xyz="-3.35070604631623E-08 0.0113462692290319 -0.0207440591174633"/><mass value="0.154644776019609"/><inertia ixx="3.28942503506928E-05" ixy="1.75986692195613E-11" ixz="1.96284103912038E-10" iyy="1.71881147064278E-05" iyz="1.17033047177854E-08" izz="2.79113895784957E-05"/></inertial><visual><origin rpy="0 0 0" xyz="0 0 0"/><geometry><mesh filename="package://robokit_mv_description/meshes/Waist.STL"/></geometry><material name=""><color rgba="0.792156862745098 0.819607843137255 0.933333333333333 1"/></material></visual><collision><origin rpy="0 0 0" xyz="0 0 0"/><geometry><mesh filename="package://robokit_mv_description/meshes/Waist.STL"/></geometry></collision></link><joint name="pelvis_yaw" type="continuous"><origin rpy="0 0 0" xyz="0 0.02575 -0.00150000000000035"/><parent link="trunk_1"/><child link="Waist"/><axis xyz="0 0 -1"/><limit effort="2.5" velocity="8"/></joint><link name="Leg_Joint_Left01"><inertial><origin rpy="0 0 0" xyz="-3.19559579495081E-05 -0.0072042644181005 -0.0134140426609431"/><mass value="0.0512846295242101"/><inertia ixx="8.54007241396861E-06" ixy="1.78031687529191E-08" ixz="-6.54492012415178E-11" iyy="5.85930623260801E-06" iyz="1.12013781366265E-09" izz="1.1112438880465E-05"/></inertial><visual><origin rpy="0 0 0" xyz="0 0 0"/><geometry><mesh filename="package://robokit_mv_description/meshes/Leg_Joint_Left01.STL"/></geometry><material name=""><color rgba="0.752941176470588 0.752941176470588 0.752941176470588 1"/></material></visual><collision><origin rpy="0 0 0" xyz="0 0 0"/><geometry><mesh filename="package://robokit_mv_description/meshes/Leg_Joint_Left01.STL"/></geometry></collision></link><joint name="left_hip_yaw" type="continuous"><origin rpy="0 0 1.5707963267949" xyz="0.0215 0 -0.0404999999999994"/><parent link="Waist"/><child link="Leg_Joint_Left01"/><axis xyz="0 0 1"/><limit effort="2.5" velocity="8"/></joint><link name="Leg_Joint_Left02"><inertial><origin rpy="0 0 0" xyz="9.98775832880272E-05 -0.0209999999999998 -0.000150122416631461"/><mass value="0.020080538717293"/><inertia ixx="3.02313197281685E-06" ixy="-3.25488486275295E-08" ixz="9.383785217782E-12" iyy="4.48391280889875E-06" iyz="3.2548848627529E-08" izz="3.02313197281685E-06"/></inertial><visual><origin rpy="0 0 0" xyz="0 0 0"/><geometry><mesh filename="package://robokit_mv_description/meshes/Leg_Joint_Left02.STL"/></geometry><material name=""><color rgba="0.752941176470588 0.752941176470588 0.752941176470588 1"/></material></visual><collision><origin rpy="0 0 0" xyz="0 0 0"/><geometry><mesh filename="package://robokit_mv_description/meshes/Leg_Joint_Left02.STL"/></geometry></collision></link><joint name="left_hip_roll" type="continuous"><origin rpy="1.5707963267949 0 -1.5707963267949" xyz="0 -0.0185000000000018 -0.0145000000000005"/><parent link="Leg_Joint_Left01"/><child link="Leg_Joint_Left02"/><axis xyz="0 0 1"/><limit effort="2.5" velocity="8"/></joint><link name="Hip_Left"><inertial><origin rpy="0 0 0" xyz="-0.000282404195646159 0.00272640816197481 -0.0339546508546348"/><mass value="0.101150064064768"/><inertia ixx="1.88876210634111E-05" ixy="8.9065000967457E-09" ixz="-2.36228892041296E-09" iyy="2.13238211554501E-05" iyz="-1.63179903836981E-06" izz="1.22923575894604E-05"/></inertial><visual><origin rpy="0 0 0" xyz="0 0 0"/><geometry><mesh filename="package://robokit_mv_description/meshes/Hip_Left.STL"/></geometry><material name=""><color rgba="0.752941176470588 0.752941176470588 0.752941176470588 1"/></material></visual><collision><origin rpy="0 0 0" xyz="0 0 0"/><geometry><mesh filename="package://robokit_mv_description/meshes/Hip_Left.STL"/></geometry></collision></link><joint name="left_hip_pitch" type="continuous"><origin rpy="1.5707963267949 0 3.14159265358979" xyz="0 -0.0420000000000003 -0.000249999999987944"/><parent link="Leg_Joint_Left02"/><child link="Hip_Left"/><axis xyz="-1 0 0"/><limit effort="2.5" lower="-2.0" upper="2.0" velocity="8"/></joint><link name="Shin_Left"><inertial><origin rpy="0 0 0" xyz="-5.64736112874872E-05 0.00340392461866844 -0.0445798634118628"/><mass value="0.0646126841894407"/><inertia ixx="1.0850452160879E-05" ixy="1.69133317870829E-08" ixz="-1.27880202966444E-08" iyy="1.3871985706539E-05" iyz="-1.4231710521206E-06" izz="8.26789843761026E-06"/></inertial><visual><origin rpy="0 0 0" xyz="0 0 0"/><geometry><mesh filename="package://robokit_mv_description/meshes/Shin_Left.STL"/></geometry><material name=""><color rgba="0.752941176470588 0.752941176470588 0.752941176470588 1"/></material></visual><collision><origin rpy="0 0 0" xyz="0 0 0"/><geometry><mesh filename="package://robokit_mv_description/meshes/Shin_Left.STL"/></geometry></collision></link><joint name="left_knee" type="continuous"><origin rpy="0 0 0" xyz="0 0 -0.0654640764655605"/><parent link="Hip_Left"/><child link="Shin_Left"/><axis xyz="-1 0 0"/><limit effort="2.5" velocity="8"/></joint><link name="Leg_Joint_Left03"><inertial><origin rpy="0 0 0" xyz="-0.030640119418525 -0.000388057782434073 2.66648307124043E-05"/><mass value="0.0613248988336405"/><inertia ixx="1.33543952679878E-05" ixy="3.36541996948923E-08" ixz="5.05990218472107E-11" iyy="6.57220132764364E-06" iyz="-1.77984890340568E-08" izz="1.08503092781389E-05"/></inertial><visual><origin rpy="0 0 0" xyz="0 0 0"/><geometry><mesh filename="package://robokit_mv_description/meshes/Leg_Joint_Left03.STL"/></geometry><material name=""><color rgba="0.752941176470588 0.752941176470588 0.752941176470588 1"/></material></visual><collision><origin rpy="0 0 0" xyz="0 0 0"/><geometry><mesh filename="package://robokit_mv_description/meshes/Leg_Joint_Left03.STL"/></geometry></collision></link><joint name="left_ankle_pitch" type="continuous"><origin rpy="1.5707963267948 -1.5707963267949 0" xyz="0 0 -0.0638038486636514"/><parent link="Shin_Left"/><child link="Leg_Joint_Left03"/><axis xyz="0 1 0"/><limit effort="2.5" velocity="8"/></joint><link name="Foot_Right"><inertial><origin rpy="0 0 0" xyz="-0.0211401926421241 -0.000636427862619866 -0.0203588030920013"/><mass value="0.0398739900019891"/><inertia ixx="2.89897310343288E-05" ixy="-1.65588139005645E-10" ixz="-2.55849239760451E-07" iyy="1.50579151043644E-05" iyz="-1.85448230993013E-10" izz="4.31603705562003E-05"/></inertial><visual><origin rpy="0 0 0" xyz="0 0 0"/><geometry><mesh filename="package://robokit_mv_description/meshes/Foot_Right.STL"/></geometry><material name=""><color rgba="1 1 1 1"/></material></visual><collision><origin rpy="0 0 0" xyz="0 0 0"/><geometry><mesh filename="package://robokit_mv_description/meshes/Foot_Right.STL"/></geometry></collision></link><joint name="left_ankle_roll" type="continuous"><origin rpy="-1.57079632679494 0 -1.57079632679491" xyz="-0.0354999999999987 -0.0115000000000029 0"/><parent link="Leg_Joint_Left03"/><child link="Foot_Right"/><axis xyz="0 1 0"/><limit effort="2.5" velocity="8"/></joint><link name="right_foot"><inertial><origin rpy="0 0 0" xyz="-6.93889390390723E-16 -2.42628833690972E-13 0"/><mass value="1.27499999999986E-07"/><inertia ixx="5.31249999999884E-15" ixy="-4.7468386299076E-32" ixz="-8.35508899605433E-32" iyy="5.31249999999884E-15" iyz="-2.08877224901163E-32" izz="5.31249999999943E-15"/></inertial><visual><origin rpy="0 0 0" xyz="0 0 0"/><geometry><mesh filename="package://robokit_mv_description/meshes/right_foot.STL"/></geometry><material name=""><color rgba="0.792156862745098 0.819607843137255 0.933333333333333 1"/></material></visual><collision><origin rpy="0 0 0" xyz="0 0 0"/><geometry><mesh filename="package://robokit_mv_description/meshes/right_foot.STL"/></geometry></collision></link><joint name="right_foot_frame" type="fixed"><origin rpy="0 0 3.14159265358979" xyz="0.0794999999999962 0.000749999999970892 -0.0254068939380563"/><parent link="Foot_Right"/><child link="right_foot"/><axis xyz="0 0 0"/></joint><link name="Leg_Joint_Right01"><inertial><origin rpy="0 0 0" xyz="-3.19558301462713E-05 0.00720426423571851 -0.0134138401732526"/><mass value="0.0512846290411205"/><inertia ixx="8.54007241380024E-06" ixy="-1.77984869107575E-08" ixz="6.54480760389324E-11" iyy="5.85930619302243E-06" iyz="-1.08494089712304E-09" izz="1.11124388389682E-05"/></inertial><visual><origin rpy="0 0 0" xyz="0 0 0"/><geometry><mesh filename="package://robokit_mv_description/meshes/Leg_Joint_Right01.STL"/></geometry><material name=""><color rgba="0.752941176470588 0.752941176470588 0.752941176470588 1"/></material></visual><collision><origin rpy="0 0 0" xyz="0 0 0"/><geometry><mesh filename="package://robokit_mv_description/meshes/Leg_Joint_Right01.STL"/></geometry></collision></link><joint name="right_hip_yaw" type="continuous"><origin rpy="0 0 1.5707963267949" xyz="-0.0215 0 -0.0404999999999991"/><parent link="Waist"/><child link="Leg_Joint_Right01"/><axis xyz="0 0 1"/><limit effort="2.5" velocity="8"/></joint><link name="Leg_Joint_Right02"><inertial><origin rpy="0 0 0" xyz="0.000100239125274626 -0.0209999999999996 0.000149760874804655"/><mass value="0.020080538717293"/><inertia ixx="3.02313197281684E-06" ixy="-3.25192170197193E-08" ixz="9.38378521866861E-12" iyy="4.48391280889874E-06" iyz="-3.25192170197182E-08" izz="3.02313197281685E-06"/></inertial><visual><origin rpy="0 0 0" xyz="0 0 0"/><geometry><mesh filename="package://robokit_mv_description/meshes/Leg_Joint_Right02.STL"/></geometry><material name=""><color rgba="0.752941176470588 0.752941176470588 0.752941176470588 1"/></material></visual><collision><origin rpy="0 0 0" xyz="0 0 0"/><geometry><mesh filename="package://robokit_mv_description/meshes/Leg_Joint_Right02.STL"/></geometry></collision></link><joint name="right_hip_roll" type="continuous"><origin rpy="1.5707963267949 0 1.5707963267949" xyz="0 0.0185 -0.0145000000000004"/><parent link="Leg_Joint_Right01"/><child link="Leg_Joint_Right02"/><axis xyz="0 0 1"/><limit effort="2.5" velocity="8"/></joint><link name="Hip_Right"><inertial><origin rpy="0 0 0" xyz="-0.000282404257601537 -0.00272642169597793 -0.0339545995512656"/><mass value="0.101150064618055"/><inertia ixx="1.88876210655236E-05" ixy="-8.92363142970319E-09" ixz="-2.29675028061216E-09" iyy="2.13238510225186E-05" iyz="1.63174586641569E-06" izz="1.22923278086204E-05"/></inertial><visual><origin rpy="0 0 0" xyz="0 0 0"/><geometry><mesh filename="package://robokit_mv_description/meshes/Hip_Right.STL"/></geometry><material name=""><color rgba="0.752941176470588 0.752941176470588 0.752941176470588 1"/></material></visual><collision><origin rpy="0 0 0" xyz="0 0 0"/><geometry><mesh filename="package://robokit_mv_description/meshes/Hip_Right.STL"/></geometry></collision></link><joint name="right_hip_pitch" type="continuous"><origin rpy="1.5707963267949 0 3.14159265358979" xyz="0 -0.0420000000000002 0.000249999999944236"/><parent link="Leg_Joint_Right02"/><child link="Hip_Right"/><axis xyz="1 0 0"/><limit effort="2.5" lower="-2.0" upper="2.0" velocity="8"/></joint><link name="Shin_Right"><inertial><origin rpy="0 0 0" xyz="-5.64745603120129E-05 -0.00340366862625934 -0.0445798704617521"/><mass value="0.0646126738231139"/><inertia ixx="1.08504496680133E-05" ixy="-1.67777611674612E-08" ixz="-1.27621188774935E-08" iyy="1.38720214198207E-05" iyz="1.42316083765014E-06" izz="8.26785555781953E-06"/></inertial><visual><origin rpy="0 0 0" xyz="0 0 0"/><geometry><mesh filename="package://robokit_mv_description/meshes/Shin_Right.STL"/></geometry><material name=""><color rgba="0.752941176470588 0.752941176470588 0.752941176470588 1"/></material></visual><collision><origin rpy="0 0 0" xyz="0 0 0"/><geometry><mesh filename="package://robokit_mv_description/meshes/Shin_Right.STL"/></geometry></collision></link><joint name="right_knee" type="continuous"><origin rpy="0 0 0" xyz="0 0 -0.0654640764655562"/><parent link="Hip_Right"/><child link="Shin_Right"/><axis xyz="-1 0 0"/><limit effort="2.5" velocity="8"/></joint><link name="Leg_Joint_Right03"><inertial><origin rpy="0 0 0" xyz="-0.0306399501647063 -0.000388057791759926 -2.67832438580681E-05"/><mass value="0.0613248988298913"/><inertia ixx="1.33543952422323E-05" ixy="3.36189859395737E-08" ixz="5.06130863311831E-11" iyy="6.57220131746516E-06" iyz="1.78031554053221E-08" izz="1.08503092622876E-05"/></inertial><visual><origin rpy="0 0 0" xyz="0 0 0"/><geometry><mesh filename="package://robokit_mv_description/meshes/Leg_Joint_Right03.STL"/></geometry><material name=""><color rgba="0.752941176470588 0.752941176470588 0.752941176470588 1"/></material></visual><collision><origin rpy="0 0 0" xyz="0 0 0"/><geometry><mesh filename="package://robokit_mv_description/meshes/Leg_Joint_Right03.STL"/></geometry></collision></link><joint name="right_ankle_pitch" type="continuous"><origin rpy="1.5707963267949 -1.5707963267949 0" xyz="0 0 -0.0638038486633716"/><parent link="Shin_Right"/><child link="Leg_Joint_Right03"/><axis xyz="0 1 0"/><limit effort="2.5" velocity="8"/></joint><link name="Foot_Left"><inertial><origin rpy="0 0 0" xyz="-0.0211401926421647 -0.000636427863859361 -0.0203588030922825"/><mass value="0.0398739900019891"/><inertia ixx="2.89897310343288E-05" ixy="-1.65588140489864E-10" ixz="-2.55849239760451E-07" iyy="1.50579151043644E-05" iyz="-1.8544822956272E-10" izz="4.31603705562003E-05"/></inertial><visual><origin rpy="0 0 0" xyz="0 0 0"/><geometry><mesh filename="package://robokit_mv_description/meshes/Foot_Left.STL"/></geometry><material name=""><color rgba="0.792156862745098 0.819607843137255 0.933333333333333 1"/></material></visual><collision><origin rpy="0 0 0" xyz="0 0 0"/><geometry><mesh filename="package://robokit_mv_description/meshes/Foot_Left.STL"/></geometry></collision></link><joint name="right_anke_roll" type="continuous"><origin rpy="-1.57079632679489 0 -1.57079632679489" xyz="-0.0354999999999995 -0.0115000000000478 0"/><parent link="Leg_Joint_Right03"/><child link="Foot_Left"/><axis xyz="0 1 0"/><limit effort="2.5" velocity="8"/></joint><link name="left_foot"><inertial><origin rpy="0 0 0" xyz="1.17961196366423E-16 -9.89569537424018E-13 1.11022302462516E-16"/><mass value="1.27499999999986E-07"/><inertia ixx="5.31249999999884E-15" ixy="-4.7468386299076E-32" ixz="-8.35508899605433E-32" iyy="5.31249999999884E-15" iyz="-2.08877224901163E-32" izz="5.31249999999943E-15"/></inertial><visual><origin rpy="0 0 0" xyz="0 0 0"/><geometry><mesh filename="package://robokit_mv_description/meshes/left_foot.STL"/></geometry><material name=""><color rgba="0.792156862745098 0.819607843137255 0.933333333333333 1"/></material></visual><collision><origin rpy="0 0 0" xyz="0 0 0"/><geometry><mesh filename="package://robokit_mv_description/meshes/left_foot.STL"/></geometry></collision></link><joint name="left_foot_frame" type="fixed"><origin rpy="0 0 0" xyz="0.0794999999999584 0.00124999999993657 -0.0254068939383429"/><parent link="Foot_Left"/><child link="left_foot"/><axis xyz="0 0 0"/></joint><link name="Forearm_Right"><inertial><origin rpy="0 0 0" xyz="1.87939941387327E-13 -0.0106456238604742 0.000634763144775119"/><mass value="0.00814777543988268"/><inertia ixx="2.88420328428271E-06" ixy="-2.54005497593128E-17" ixz="1.05106248414997E-14" iyy="2.45381641366332E-06" iyz="4.60366193686945E-08" izz="1.11781703961495E-06"/></inertial><visual><origin rpy="0 0 0" xyz="0 0 0"/><geometry><mesh filename="package://robokit_mv_description/meshes/Forearm_Right.STL"/></geometry><material name=""><color rgba="0.792156862745098 0.819607843137255 0.933333333333333 1"/></material></visual><collision><origin rpy="0 0 0" xyz="0 0 0"/><geometry><mesh filename="package://robokit_mv_description/meshes/Forearm_Right.STL"/></geometry></collision></link><joint name="right_shoulder_pitch" type="continuous"><origin rpy="1.5707963267949 1.5707963267949 0" xyz="-0.0511999999999879 0.0142000000000003 0.0487499999999991"/><parent link="trunk_1"/><child link="Forearm_Right"/><axis xyz="0 1 0"/><limit effort="2.5" velocity="8"/></joint><link name="Arm_Right"><inertial><origin rpy="0 0 0" xyz="-1.0104556261159E-07 -0.00618643921558165 0.0345016442183754"/><mass value="0.10267355995043"/><inertia ixx="2.17355163845237E-05" ixy="-8.30277185136509E-11" ixz="-4.7828269846734E-11" iyy="1.41158682546047E-05" iyz="1.2680499330184E-07" izz="1.57397379865535E-05"/></inertial><visual><origin rpy="0 0 0" xyz="0 0 0"/><geometry><mesh filename="package://robokit_mv_description/meshes/Arm_Right.STL"/></geometry><material name=""><color rgba="0.752941176470588 0.752941176470588 0.752941176470588 1"/></material></visual><collision><origin rpy="0 0 0" xyz="0 0 0"/><geometry><mesh filename="package://robokit_mv_description/meshes/Arm_Right.STL"/></geometry></collision></link><joint name="right_shoulder_roll" type="continuous"><origin rpy="1.5707963267949 0 1.5707963267949" xyz="0 -0.0250000000000002 0"/><parent link="Forearm_Right"/><child link="Arm_Right"/><axis xyz="0 1 0"/><limit effort="2.5" velocity="8"/></joint><link name="Elbow_Right"><inertial><origin rpy="0 0 0" xyz="-0.0134138402456614 -0.00683871223441472 3.19559527753588E-05"/><mass value="0.0512846295229477"/><inertia ixx="1.11124388652496E-05" ixy="1.12014609962257E-09" ixz="-6.54290803370197E-11" iyy="5.85930622589019E-06" iyz="1.7798472145625E-08" izz="8.54007240557124E-06"/></inertial><visual><origin rpy="0 0 0" xyz="0 0 0"/><geometry><mesh filename="package://robokit_mv_description/meshes/Elbow_Right.STL"/></geometry><material name=""><color rgba="0.752941176470588 0.752941176470588 0.752941176470588 1"/></material></visual><collision><origin rpy="0 0 0" xyz="0 0 0"/><geometry><mesh filename="package://robokit_mv_description/meshes/Elbow_Right.STL"/></geometry></collision></link><joint name="right_shoulder_twirl" type="continuous"><origin rpy="0 1.5707963267949 0" xyz="0 -0.000499999999987961 0.0743999999999973"/><parent link="Arm_Right"/><child link="Elbow_Right"/><axis xyz="1 0 0"/><limit effort="2.5" velocity="8"/></joint><link name="Hand_Right"><inertial><origin rpy="0 0 0" xyz="-0.000298101439876611 0.0475719113939495 0.00168989365596822"/><mass value="0.0242658011097449"/><inertia ixx="5.83797255681696E-06" ixy="3.32256201052361E-08" ixz="-7.55707704208802E-08" iyy="4.3258592466132E-06" iyz="5.23267315518168E-08" izz="3.91200787990746E-06"/></inertial><visual><origin rpy="0 0 0" xyz="0 0 0"/><geometry><mesh filename="package://robokit_mv_description/meshes/Hand_Right.STL"/></geometry><material name=""><color rgba="0.752941176470588 0.752941176470588 0.752941176470588 1"/></material></visual><collision><origin rpy="0 0 0" xyz="0 0 0"/><geometry><mesh filename="package://robokit_mv_description/meshes/Hand_Right.STL"/></geometry></collision></link><joint name="right_elbow" type="continuous"><origin rpy="3.14159265358979 0 -1.5707963267949" xyz="-0.0145000000000004 0.00449999999999998 0"/><parent link="Elbow_Right"/><child link="Hand_Right"/><axis xyz="0 0 1"/><limit effort="2.5" velocity="8"/></joint><link name="Forearm_Left"><inertial><origin rpy="0 0 0" xyz="1.84262327618256E-13 -0.0106456238604513 0.000634763144775074"/><mass value="0.0081477754398827"/><inertia ixx="2.88420328428271E-06" ixy="-2.54008320405854E-17" ixz="1.05106290971958E-14" iyy="2.45381641366333E-06" iyz="4.60366193686983E-08" izz="1.11781703961495E-06"/></inertial><visual><origin rpy="0 0 0" xyz="0 0 0"/><geometry><mesh filename="package://robokit_mv_description/meshes/Forearm_Left.STL"/></geometry><material name=""><color rgba="0.792156862745098 0.819607843137255 0.933333333333333 1"/></material></visual><collision><origin rpy="0 0 0" xyz="0 0 0"/><geometry><mesh filename="package://robokit_mv_description/meshes/Forearm_Left.STL"/></geometry></collision></link><joint name="left_shoulder_pitch" type="continuous"><origin rpy="1.5707963267949 -1.5707963267949 0" xyz="0.0512000000000104 0.0142000000000005 0.0487499999999991"/><parent link="trunk_1"/><child link="Forearm_Left"/><axis xyz="0 1 0"/><limit effort="2.5" velocity="8"/></joint><link name="Arm_Left"><inertial><origin rpy="0 0 0" xyz="-1.01135898378235E-07 -0.0061864390787304 0.0345016442078851"/><mass value="0.102673558971779"/><inertia ixx="2.17355163043989E-05" ixy="-8.30337421317796E-11" ixz="-4.78357004174475E-11" iyy="1.41158682129161E-05" iyz="1.26804993301834E-07" izz="1.57397379448648E-05"/></inertial><visual><origin rpy="0 0 0" xyz="0 0 0"/><geometry><mesh filename="package://robokit_mv_description/meshes/Arm_Left.STL"/></geometry><material name=""><color rgba="0.752941176470588 0.752941176470588 0.752941176470588 1"/></material></visual><collision><origin rpy="0 0 0" xyz="0 0 0"/><geometry><mesh filename="package://robokit_mv_description/meshes/Arm_Left.STL"/></geometry></collision></link><joint name="left_shoulder_roll" type="continuous"><origin rpy="1.5707963267949 0 -1.5707963267949" xyz="0 -0.0250000000000002 0"/><parent link="Forearm_Left"/><child link="Arm_Left"/><axis xyz="0 1 0"/><limit effort="2.5" velocity="8"/></joint><link name="Elbow_Left"><inertial><origin rpy="0 0 0" xyz="-0.013414042576414 -0.00683871238402667 -3.19560756821546E-05"/><mass value="0.0512846299543346"/><inertia ixx="1.11124388792797E-05" ixy="1.08495341016806E-09" ixz="-6.54268039409115E-11" iyy="5.85930625627109E-06" iyz="-1.78031865966666E-08" izz="8.54007239041879E-06"/></inertial><visual><origin rpy="0 0 0" xyz="0 0 0"/><geometry><mesh filename="package://robokit_mv_description/meshes/Elbow_Left.STL"/></geometry><material name=""><color rgba="0.752941176470588 0.752941176470588 0.752941176470588 1"/></material></visual><collision><origin rpy="0 0 0" xyz="0 0 0"/><geometry><mesh filename="package://robokit_mv_description/meshes/Elbow_Left.STL"/></geometry></collision></link><joint name="left_shoulder_twirl" type="continuous"><origin rpy="0 1.5707963267949 0" xyz="0 -0.000499999999987795 0.0743999999999975"/><parent link="Arm_Left"/><child link="Elbow_Left"/><axis xyz="1 0 0"/><limit effort="2.5" velocity="8"/></joint><link name="Hand_Left"><inertial><origin rpy="0 0 0" xyz="0.000289371875005124 -0.0426734248516597 -0.00207056730651169"/><mass value="0.0207040754614249"/><inertia ixx="5.55100255153863E-06" ixy="2.01424224463897E-08" ixz="-6.34860431629677E-08" iyy="4.08638271063399E-06" iyz="9.1123687608939E-08" izz="3.63770502904564E-06"/></inertial><visual><origin rpy="0 0 0" xyz="0 0 0"/><geometry><mesh filename="package://robokit_mv_description/meshes/Hand_Left.STL"/></geometry><material name=""><color rgba="0.752941176470588 0.752941176470588 0.752941176470588 1"/></material></visual><collision><origin rpy="0 0 0" xyz="0 0 0"/><geometry><mesh filename="package://robokit_mv_description/meshes/Hand_Left.STL"/></geometry></collision></link><joint name="left_elbow" type="continuous"><origin rpy="3.14159265358979 0 1.5707963267949" xyz="-0.0145000000000001 0.0045 0"/><parent link="Elbow_Left"/><child link="Hand_Left"/><axis xyz="0 0 1"/><limit effort="2.5" velocity="8"/></joint><link name="Neck"><inertial><origin rpy="0 0 0" xyz="-7.2054385518975E-05 0.0136691972667993 -3.08512760206769E-07"/><mass value="0.0122170870464977"/><inertia ixx="9.39329341934082E-07" ixy="-3.69627304705553E-08" ixz="-7.7052466077669E-11" iyy="2.68533956388329E-06" iyz="7.59503760503805E-11" izz="2.9149671733215E-06"/></inertial><visual><origin rpy="0 0 0" xyz="0 0 0"/><geometry><mesh filename="package://robokit_mv_description/meshes/Neck.STL"/></geometry><material name=""><color rgba="0.752941176470588 0.752941176470588 0.752941176470588 1"/></material></visual><collision><origin rpy="0 0 0" xyz="0 0 0"/><geometry><mesh filename="package://robokit_mv_description/meshes/Neck.STL"/></geometry></collision></link><joint name="head_yaw" type="continuous"><origin rpy="1.57079632679489 0 -3.14159265358979" xyz="0 0.0142000000000002 0.0615499999999989"/><parent link="trunk_1"/><child link="Neck"/><axis xyz="0 1 0"/><limit effort="2.5" velocity="8"/></joint><link name="Head"><inertial><origin rpy="0 0 0" xyz="-0.0108911606011029 -0.0332077007101556 4.14816350767002E-05"/><mass value="0.163135245541874"/><inertia ixx="0.000103364518648403" ixy="1.27002914983976E-06" ixz="-1.29437528885219E-09" iyy="7.64163530592585E-05" iyz="7.07971794361272E-07" izz="4.95269620055087E-05"/></inertial><visual><origin rpy="0 0 0" xyz="0 0 0"/><geometry><mesh filename="package://robokit_mv_description/meshes/Head.STL"/></geometry><material name=""><color rgba="0.792156862745098 0.819607843137255 0.933333333333333 1"/></material></visual><collision><origin rpy="0 0 0" xyz="0 0 0"/><geometry><mesh filename="package://robokit_mv_description/meshes/Head.STL"/></geometry></collision></link><joint name="head_pitch" type="continuous"><origin rpy="1.57079632679533 1.55915844493874 -1.57079632679447" xyz="0 0.0282 0"/><parent link="Neck"/><child link="Head"/><axis xyz="0 0 1"/><limit effort="2.5" velocity="8"/></joint><link name="camera"><inertial><origin rpy="0 0 0" xyz="-4.06575814682064E-20 2.77555756156289E-17 0"/><mass value="1.275E-07"/><inertia ixx="5.31250000000001E-15" ixy="-2.38304359369697E-31" ixz="1.3101927625964E-31" iyy="5.31250000000001E-15" iyz="2.35457888710234E-31" izz="5.31250000000001E-15"/></inertial><visual><origin rpy="0 0 0" xyz="0 0 0"/><geometry><mesh filename="package://robokit_mv_description/meshes/camera.STL"/></geometry><material name=""><color rgba="0.792156862745098 0.819607843137255 0.933333333333333 1"/></material></visual><collision><origin rpy="0 0 0" xyz="0 0 0"/><geometry><mesh filename="package://robokit_mv_description/meshes/camera.STL"/></geometry></collision></link><joint name="camera_frame" type="fixed"><origin rpy="0.0116378818561755 -1.5707963267949 0" xyz="0.0116432919967299 -0.0436082735831216 0.000100000000012143"/><parent link="Head"/><child link="camera"/><axis xyz="0 0 0"/></joint><link name="Backpack"><inertial><origin rpy="0 0 0" xyz="0.000227548569987629 -0.00537793203761297 -0.0283796013461026"/><mass value="0.0432975649644979"/><inertia ixx="4.12051433748935E-05" ixy="1.18407098634176E-11" ixz="1.75912893882631E-13" iyy="7.360946260012E-05" iyz="-6.64793799342586E-13" izz="9.46529186579802E-05"/></inertial><visual><origin rpy="0 0 0" xyz="0 0 0"/><geometry><mesh filename="package://robokit_mv_description/meshes/Backpack.STL"/></geometry><material name=""><color rgba="0.792156862745098 0.819607843137255 0.933333333333333 1"/></material></visual><collision><origin rpy="0 0 0" xyz="0 0 0"/><geometry><mesh filename="package://robokit_mv_description/meshes/Backpack.STL"/></geometry></collision></link><joint name="Backpack_fix" type="fixed"><origin rpy="1.5707963267949 0 0" xyz="-0.00022754807029518 0.0515 0.0339403012770695"/><parent link="trunk_1"/><child link="Backpack"/><axis xyz="0 0 0"/></joint><link name="base_link"><inertial><origin rpy="0 0 0" xyz="7.02963443262805E-06 0.000166826979018653 -0.0108079385411631"/><mass value="1.275E-07"/><inertia ixx="5.31250000000002E-15" ixy="-4.7468386299164E-32" ixz="8.35508899604758E-32" iyy="5.31250000000002E-15" iyz="-2.0887722490119E-32" izz="5.31250000000002E-15"/></inertial><visual><origin rpy="0 0 0" xyz="0 0 0"/><geometry><mesh filename="package://robokit_mv_description/meshes/trunk.STL"/></geometry><material name=""><color rgba="0.792156862745098 0.819607843137255 0.933333333333333 1"/></material></visual><collision><origin rpy="0 0 0" xyz="0 0 0"/><geometry><mesh filename="package://robokit_mv_description/meshes/trunk.STL"/></geometry></collision></link><joint name="trunk_frame" type="fixed"><origin rpy="0 0 0" xyz="-0.000150218352888387 0.0256574854752784 -0.0450598564129154"/><parent link="trunk_1"/><child link="base_link"/><axis xyz="0 0 0"/></joint><link name="head_base"><inertial><origin rpy="0 0 0" xyz="-1.52597296943921E-15 0 1.38777878078145E-17"/><mass value="1.275E-07"/><inertia ixx="5.31250000000002E-15" ixy="-4.7468386299164E-32" ixz="8.35508899604757E-32" iyy="5.31250000000002E-15" iyz="-2.0887722490119E-32" izz="5.31250000000002E-15"/></inertial><visual><origin rpy="0 0 0" xyz="0 0 0"/><geometry><mesh filename="package://robokit_mv_description/meshes/head_base.STL"/></geometry><material name=""><color rgba="0.792156862745098 0.819607843137255 0.933333333333333 1"/></material></visual><collision><origin rpy="0 0 0" xyz="0 0 0"/><geometry><mesh filename="package://robokit_mv_description/meshes/head_base.STL"/></geometry></collision></link><joint name="head_base_frame" type="fixed"><origin rpy="0 0 0" xyz="0 0.0142000000000002 0.0656999999999994"/><parent link="trunk_1"/><child link="head_base"/><axis xyz="0 0 0"/></joint><!-- <link
    name="num_01">
    <inertial>
      <origin
        xyz="0.0208235381701784 0.0265368431678545 -0.000173869427509511"
        rpy="0 0 0" />
      <mass
        value="0.000570874530441625" />
      <inertia
        ixx="1.1722452097598E-07"
        ixy="9.49535850682138E-09"
        ixz="6.28203453068967E-10"
        iyy="1.07183362337616E-08"
        iyz="-8.3484233461281E-09"
        izz="1.25464724831805E-07" />
    </inertial>
    <visual>
      <origin
        xyz="0 0 0"
        rpy="0 0 0" />
      <geometry>
        <mesh
          filename="package://robokit_mv_description/meshes/num_01.STL" />
      </geometry>
      <material
        name="">
        <color
          rgba="0.792156862745098 0.819607843137255 0.933333333333333 1" />
      </material>
    </visual>
    <collision>
      <origin
        xyz="0 0 0"
        rpy="0 0 0" />
      <geometry>
        <mesh
          filename="package://robokit_mv_description/meshes/num_01.STL" />
      </geometry>
    </collision>
  </link>
  <joint
    name="num_01_fix"
    type="fixed">
    <origin
      xyz="-0.001141 -0.025 0.0050692"
      rpy="1.5708 0 0" />
    <parent
      link="trunk_1" />
    <child
      link="num_01" />
    <axis
      xyz="0 0 0" />
  </joint>
  <link
    name="num_02">
    <inertial>
      <origin
        xyz="0.0189520407987391 0.0218434267027871 -0.00104528071787012"
        rpy="0 0 0" />
      <mass
        value="0.00102770122327197" />
      <inertia
        ixx="3.09986548398344E-07"
        ixy="-1.99030363842269E-08"
        ixz="-1.7895289064832E-09"
        iyy="8.55789388484911E-08"
        iyz="-2.93939353386446E-08"
        izz="3.8662899051372E-07" />
    </inertial>
    <visual>
      <origin
        xyz="0 0 0"
        rpy="0 0 0" />
      <geometry>
        <mesh
          filename="package://robokit_mv_description/meshes/num_02.STL" />
      </geometry>
      <material
        name="">
        <color
          rgba="0.792156862745098 0.819607843137255 0.933333333333333 1" />
      </material>
    </visual>
    <collision>
      <origin
        xyz="0 0 0"
        rpy="0 0 0" />
      <geometry>
        <mesh
          filename="package://robokit_mv_description/meshes/num_02.STL" />
      </geometry>
    </collision>
  </link>
  <joint
    name="num_02_fix"
    type="fixed">
    <origin
      xyz="-0.00011538 -0.025 0.0050692"
      rpy="1.5708 0 0" />
    <parent
      link="trunk_1" />
    <child
      link="num_02" />
    <axis
      xyz="0 0 0" />
  </joint>
  <link
    name="num_03">
    <inertial>
      <origin
        xyz="0.0211901958724706 0.0233139611805824 -0.000666381477769332"
        rpy="0 0 0" />
      <mass
        value="0.000940537354254539" />
      <inertia
        ixx="2.55000924546634E-07"
        ixy="1.3637593294189E-09"
        ixz="-2.38871281684249E-09"
        iyy="7.24884975138308E-08"
        iyz="-2.08866264694033E-08"
        izz="3.2135374477828E-07" />
    </inertial>
    <visual>
      <origin
        xyz="0 0 0"
        rpy="0 0 0" />
      <geometry>
        <mesh
          filename="package://robokit_mv_description/meshes/num_03.STL" />
      </geometry>
      <material
        name="">
        <color
          rgba="0.792156862745098 0.819607843137255 0.933333333333333 1" />
      </material>
    </visual>
    <collision>
      <origin
        xyz="0 0 0"
        rpy="0 0 0" />
      <geometry>
        <mesh
          filename="package://robokit_mv_description/meshes/num_03.STL" />
      </geometry>
    </collision>
  </link>
  <joint
    name="num_03_fix"
    type="fixed">
    <origin
      xyz="-0.00137139423076944 -0.025 0.00506924133700464"
      rpy="1.5707963267949 0 0" />
    <parent
      link="trunk_1" />
    <child
      link="num_03" />
    <axis
      xyz="0 0 0" />
  </joint>
  <link
    name="num_04">
    <inertial>
      <origin
        xyz="0.0198973231938261 0.0231312706924585 6.73560822704103E-05"
        rpy="0 0 0" />
      <mass
        value="0.000978360744785296" />
      <inertia
        ixx="1.39624720158043E-07"
        ixy="-6.49526518603619E-09"
        ixz="2.03318195408202E-09"
        iyy="6.75674126758199E-08"
        iyz="-7.55883257241574E-09"
        izz="2.04471973758685E-07" />
    </inertial>
    <visual>
      <origin
        xyz="0 0 0"
        rpy="0 0 0" />
      <geometry>
        <mesh
          filename="package://robokit_mv_description/meshes/num_04.STL" />
      </geometry>
      <material
        name="">
        <color
          rgba="0.792156862745098 0.819607843137255 0.933333333333333 1" />
      </material>
    </visual>
    <collision>
      <origin
        xyz="0 0 0"
        rpy="0 0 0" />
      <geometry>
        <mesh
          filename="package://robokit_mv_description/meshes/num_04.STL" />
      </geometry>
    </collision>
  </link>
  <joint
    name="num_04_fix"
    type="fixed">
    <origin
      xyz="-0.00075641 -0.025 0.0050692"
      rpy="1.5708 0 0" />
    <parent
      link="trunk_1" />
    <child
      link="num_04" />
    <axis
      xyz="0 0 0" />
  </joint>
  <link
    name="num_05">
    <inertial>
      <origin
        xyz="0.0192253725031374 0.0242270562964091 -0.000540076322432949"
        rpy="0 0 0" />
      <mass
        value="0.00104853124248246" />
      <inertia
        ixx="2.66941839063471E-07"
        ixy="1.02844037705421E-08"
        ixz="-4.91429452570459E-10"
        iyy="8.7152146989004E-08"
        iyz="-2.15685255707603E-08"
        izz="3.47722071568518E-07" />
    </inertial>
    <visual>
      <origin
        xyz="0 0 0"
        rpy="0 0 0" />
      <geometry>
        <mesh
          filename="package://robokit_mv_description/meshes/num_05.STL" />
      </geometry>
      <material
        name="">
        <color
          rgba="0.792156862745098 0.819607843137255 0.933333333333333 1" />
      </material>
    </visual>
    <collision>
      <origin
        xyz="0 0 0"
        rpy="0 0 0" />
      <geometry>
        <mesh
          filename="package://robokit_mv_description/meshes/num_05.STL" />
      </geometry>
    </collision>
  </link>
  <joint
    name="num_05_fix"
    type="fixed">
    <origin
      xyz="0.0018076923076921 -0.025 0.00506924133700464"
      rpy="1.5707963267949 0 0" />
    <parent
      link="trunk_1" />
    <child
      link="num_05" />
    <axis
      xyz="0 0 0" />
  </joint> --><!-- <link
    name="number_01">
    <inertial>
      <origin
        xyz="0.0207776517703959 0.027021682074266 0.000499999999999987"
        rpy="0 0 0" />
      <mass
        value="0.000555953010570228" />
      <inertia
        ixx="1.08098560714746E-07"
        ixy="9.07910123965812E-09"
        ixz="5.02557000201468E-25"
        iyy="9.43341930505194E-09"
        iyz="3.47332362410589E-24"
        izz="1.17439320018073E-07" />
    </inertial>
    <visual>
      <origin
        xyz="0 0 0"
        rpy="0 0 0" />
      <geometry>
        <mesh
          filename="package://robokit_mv_description/meshes/number_01.STL" />
      </geometry>
      <material
        name="">
        <color
          rgba="0.792156862745098 0.819607843137255 0.933333333333333 1" />
      </material>
    </visual>
    <collision>
      <origin
        xyz="0 0 0"
        rpy="0 0 0" />
      <geometry>
        <mesh
          filename="package://robokit_mv_description/meshes/number_01.STL" />
      </geometry>
    </collision>
  </link>
  <joint
    name="number_01_fix"
    type="fixed">
    <origin
      xyz="0.005641 0.094 0.0038166"
      rpy="1.5708 0 3.1416" />
    <parent
      link="trunk_1" />
    <child
      link="number_01" />
    <axis
      xyz="0 0 0" />
  </joint> --><!-- <link
    name="number_02">
    <inertial>
      <origin
        xyz="0.0190153902695852 0.0228463602851654 0.00049999476187812"
        rpy="0 0 0" />
      <mass
        value="0.000968513691392372" />
      <inertia
        ixx="2.81539895357361E-07"
        ixy="-1.88228730307683E-08"
        ixz="-5.3553055356393E-14"
        iyy="7.61529446529568E-08"
        iyz="-2.40831981355288E-14"
        izz="3.57531410578623E-07" />
    </inertial>
    <visual>
      <origin
        xyz="0 0 0"
        rpy="0 0 0" />
      <geometry>
        <mesh
          filename="package://robokit_mv_description/meshes/number_02.STL" />
      </geometry>
      <material
        name="">
        <color
          rgba="0.792156862745098 0.819607843137255 0.933333333333333 1" />
      </material>
    </visual>
    <collision>
      <origin
        xyz="0 0 0"
        rpy="0 0 0" />
      <geometry>
        <mesh
          filename="package://robokit_mv_description/meshes/number_02.STL" />
      </geometry>
    </collision>
  </link>
  <joint
    name="number_02_fix"
    type="fixed">
    <origin
      xyz="0.00461538461538441 0.094 0.00381656939476953"
      rpy="1.5707963267949 0 -3.14159265358979" />
    <parent
      link="trunk_1" />
    <child
      link="number_02" />
    <axis
      xyz="0 0 0" />
  </joint>
  <link
    name="number_03">
    <inertial>
      <origin
        xyz="0.0212885651754026 0.024074824758715 0.000499995395719502"
        rpy="0 0 0" />
      <mass
        value="0.00089889558156857" />
      <inertia
        ixx="2.3422406525786E-07"
        ixy="2.88673500463855E-09"
        ixz="1.81887806696507E-15"
        iyy="6.72055852829715E-08"
        iyz="1.67693393159953E-14"
        izz="3.01279827373794E-07" />
    </inertial>
    <visual>
      <origin
        xyz="0 0 0"
        rpy="0 0 0" />
      <geometry>
        <mesh
          filename="package://robokit_mv_description/meshes/number_03.STL" />
      </geometry>
      <material
        name="">
        <color
          rgba="0.792156862745098 0.819607843137255 0.933333333333333 1" />
      </material>
    </visual>
    <collision>
      <origin
        xyz="0 0 0"
        rpy="0 0 0" />
      <geometry>
        <mesh
          filename="package://robokit_mv_description/meshes/number_03.STL" />
      </geometry>
    </collision>
  </link>
  <joint
    name="number_03_fix"
    type="fixed">
    <origin
      xyz="0.0058714 0.094 0.0045624"
      rpy="1.5708 0 -3.1416" />
    <parent
      link="trunk_1" />
    <child
      link="number_03" />
    <axis
      xyz="0 0 0" />
  </joint>
  <link
    name="number_04">
    <inertial>
      <origin
        xyz="0.0198178458364149 0.023393768005545 0.0005"
        rpy="0 0 0" />
      <mass
        value="0.000962652965096719" />
      <inertia
        ixx="1.32494740090776E-07"
        ixy="-7.81231574158938E-09"
        ixz="2.49511249737588E-25"
        iyy="6.55788803844149E-08"
        iyz="-2.88111337437569E-25"
        izz="1.97913178314342E-07" />
    </inertial>
    <visual>
      <origin
        xyz="0 0 0"
        rpy="0 0 0" />
      <geometry>
        <mesh
          filename="package://robokit_mv_description/meshes/number_04.STL" />
      </geometry>
      <material
        name="">
        <color
          rgba="0.792156862745098 0.819607843137255 0.933333333333333 1" />
      </material>
    </visual>
    <collision>
      <origin
        xyz="0 0 0"
        rpy="0 0 0" />
      <geometry>
        <mesh
          filename="package://robokit_mv_description/meshes/number_04.STL" />
      </geometry>
    </collision>
  </link>
  <joint
    name="number_04_fix"
    type="fixed">
    <origin
      xyz="0.00525641025641004 0.0940000000000001 0.00381656939476954"
      rpy="1.5707963267949 0 -3.14159265358979" />
    <parent
      link="trunk_1" />
    <child
      link="number_04" />
    <axis
      xyz="0 0 0" />
  </joint>
  <link
    name="number_05">
    <inertial>
      <origin
        xyz="0.0192374384814289 0.0249167276606165 0.000500001685692766"
        rpy="0 0 0" />
      <mass
        value="0.0010065931758337" />
      <inertia
        ixx="2.44497833408288E-07"
        ixy="1.08404205421667E-08"
        ixz="4.2571335790745E-15"
        iyy="8.19070107099453E-08"
        iyz="-2.04232961026056E-14"
        izz="3.26237084247543E-07" />
    </inertial>
    <visual>
      <origin
        xyz="0 0 0"
        rpy="0 0 0" />
      <geometry>
        <mesh
          filename="package://robokit_mv_description/meshes/number_05.STL" />
      </geometry>
      <material
        name="">
        <color
          rgba="0.792156862745098 0.819607843137255 0.933333333333333 1" />
      </material>
    </visual>
    <collision>
      <origin
        xyz="0 0 0"
        rpy="0 0 0" />
      <geometry>
        <mesh
          filename="package://robokit_mv_description/meshes/number_05.STL" />
      </geometry>
    </collision>
  </link>
  <joint
    name="number_05_fix"
    type="fixed">
    <origin
      xyz="0.0046923 0.094 0.0045624"
      rpy="1.5708 0 -3.1416" />
    <parent
      link="trunk_1" />
    <child
      link="number_05" />
    <axis
      xyz="0 0 0" />
  </joint> --></robot>